<?xml version="1.0" ?>
<!-- =================================================================================== -->
<!-- |    This document was autogenerated by xacro from mp400_description/urdf/robot.urdf.xacro | -->
<!-- |    EDITING THIS FILE BY HAND IS NOT RECOMMENDED                                 | -->
<!-- =================================================================================== -->
<!-- Materials -->
<robot name="robot" xmlns:controller="http://playerstage.sourceforge.net/gazebo/xmlschema/#controller" xmlns:interface="http://playerstage.sourceforge.net/gazebo/xmlschema/#interface" xmlns:sensor="http://playerstage.sourceforge.net/gazebo/xmlschema/#sensor" xmlns:xacro="http://ros.org/wiki/xacro">
  <material name="Schunk/LightGrey">
    <color rgba="0.7 0.7 0.7 1.0"/>
  </material>
  <material name="Schunk/DarkGrey">
    <color rgba="0.2 0.2 0.2 1.0"/>
  </material>
  <material name="Schunk/Black">
    <color rgba="0.0 0.0 0.0 1.0"/>
  </material>
  <material name="Schunk/DarkGolden">
    <color rgba="0.4 0.4 0.3 1.0"/>
  </material>
  <material name="Schunk/Blue">
    <color rgba="0.0 0.0 0.25 1.0"/>
  </material>
  <material name="Neobotix/Black">
    <color rgba="0.0 0.0 0.0 1.0"/>
  </material>
  <material name="Neobotix/Blue">
    <color rgba="0.0 0.0 0.8 1.0"/>
  </material>
  <material name="Neobotix/Green">
    <color rgba="0.0 0.8 0.0 1.0"/>
  </material>
  <!-- <material name="Neobotix/Grey">
      <color rgba="0.7 0.7 0.7 1.0"/>
  </material> -->
  <material name="Neobotix/Grey2">
    <color rgba="0.9 0.9 0.9 1.0"/>
  </material>
  <material name="Neobotix/Red">
    <color rgba="0.8 0.0 0.0 1.0"/>
  </material>
  <material name="Neobotix/White">
    <color rgba="1.0 1.0 1.0 1.0"/>
  </material>
  <material name="Neobotix/Yellow">
    <color rgba="1.0 1.0 0 10"/>
  </material>
  <link name="schunk_base_link">
    <origin rpy="0 0 0" xyz="0 0 0"/>
  </link>
  <!-- <xacro:include filename="$(find mp400_description)/urdf/materials.urdf.xacro" /> -->
  <joint name="wsg_50_anterior_gripper_joint" type="fixed">
    <origin rpy="0 0 0" xyz="0 0 0"/>
    <parent link="arm_tcp_link"/>
    <child link="wsg_50_base_link"/>
  </joint>
  <!-- BASE LINK -->
  <link name="wsg_50_base_link">
    <inertial>
      <mass value="0.25"/>
      <origin xyz="0 0 0"/>
      <!--inertia ixx="1.0" ixy="0.0" ixz="0.0"
               iyy="100.0" iyz="0.0"
               izz="1.0" /-->
      <inertia ixx="1.0" ixy="0.0" ixz="0.0" iyy="1.0" iyz="0.0" izz="1.0"/>
    </inertial>
    <visual>
      <origin rpy="0 0 0" xyz="0.0 0 0"/>
      <geometry>
        <mesh filename="package://mp400_description/meshes/wsg50/WSG50_110.stl" scale="1 1 1"/>
        <!--box size="0.146 0.05 0.0735"/-->
      </geometry>
      <material name="grey">
        <color rgba="0.5 0.5 0.5 1"/>
      </material>
    </visual>
    <collision>
      <origin rpy="0 0 0" xyz="0.0 0 0"/>
      <geometry>
        <!--box size="0.146 0.05 0.0735"/-->
        <mesh filename="package://mp400_description/meshes/wsg50/WSG50_110.stl" scale="1 1 1"/>
      </geometry>
    </collision>
  </link>
  <gazebo reference="wsg_50_base_link">
    <material>Gazebo/Grey</material>
    <turnGravityOff>false</turnGravityOff>
  </gazebo>
  <joint name="wsg_50_center_joint" type="fixed">
    <origin rpy="0 0 0" xyz="0 0 0.023"/>
    <!--origin xyz="-0.0067 0 0.049" rpy="0 0 0" /-->
    <parent link="wsg_50_base_link"/>
    <child link="wsg_50_center"/>
  </joint>
  <link name="wsg_50_center">
  </link>
  <!-- GRIPPER LEFT -->
  <joint name="wsg_50_base_joint_gripper_left" type="prismatic">
    <limit effort="1.0" lower="-0.055" upper="-0.0027" velocity="1.0"/>
    <origin rpy="0 0 0" xyz="-0.0067 0 0"/>
    <!--origin xyz="-0.0067 0 0.049" rpy="0 0 0" /-->
    <parent link="wsg_50_base_link"/>
    <child link="wsg_50_gripper_left"/>
    <dynamics damping="100" friction="100"/>
    <axis xyz="1 0 0"/>
    <limit effort="100" velocity="100"/>
  </joint>
  <transmission name="wsg_50_base_trans_left">
    <type>transmission_interface/SimpleTransmission</type>
    <joint name="wsg_50_base_joint_gripper_left">
      <hardwareInterface>hardware_interface/EffortJointInterface</hardwareInterface>
    </joint>
    <actuator name="wsg_50_base_motor_left">
      <hardwareInterface>hardware_interface/EffortJointInterface</hardwareInterface>
      <mechanicalReduction>1</mechanicalReduction>
      <motorTorqueConstant>1</motorTorqueConstant>
    </actuator>
  </transmission>
  <link name="wsg_50_gripper_left">
    <inertial>
      <mass value="0.1"/>
      <origin xyz="0 0 0"/>
      <inertia ixx="1.0" ixy="0.0" ixz="0.0" iyy="1.0" iyz="0.0" izz="1.0"/>
    </inertial>
    <visual>
      <origin rpy="0 0 0" xyz="0.0 0 0"/>
      <geometry>
        <mesh filename="package://mp400_description/meshes/wsg50/GUIDE_WSG50_110.stl" scale="0.001 0.001 0.001"/>
        <!--box size="0.0175 0.03 0.024"/-->
      </geometry>
      <material name="Neobotix/Black"/>
      <!--<color rgba="0 0 0 0"/>
	</material> -->
    </visual>
    <collision>
      <origin rpy="0 0 0" xyz="0 0 0"/>
      <geometry>
        <!--box size="0.0175 0.03 0.024"/-->
        <mesh filename="package://mp400_description/meshes/wsg50/GUIDE_WSG50_110.stl" scale="0.001 0.001 0.001"/>
      </geometry>
    </collision>
    <contact_coefficients kd="1.0" kp="1000.0" mu="0"/>
  </link>
  <gazebo reference="wsg_50_gripper_left">
    <material>Gazebo/Blue</material>
    <turnGravityOff>false</turnGravityOff>
  </gazebo>
  <!-- LEFT FINGER -->
  <joint name="wsg_50_guide_joint_finger_left" type="fixed">
    <origin rpy="0 0 0" xyz="0 0 0.023"/>
    <parent link="wsg_50_gripper_left"/>
    <child link="wsg_50_finger_left"/>
    <dynamics damping="100" friction="100"/>
    <axis xyz="1 0 0"/>
    <limit effort="100" velocity="100"/>
  </joint>
  <link name="wsg_50_finger_left">
    <inertial>
      <mass value="0.1"/>
      <origin xyz="0 0 0"/>
      <inertia ixx="1.0" ixy="0.0" ixz="0.0" iyy="1.0" iyz="0.0" izz="1.0"/>
    </inertial>
    <visual>
      <origin rpy="0 0 0" xyz="0.0 0 0"/>
      <geometry>
        <mesh filename="package://mp400_description/meshes/wsg50/WSG-FMF.stl" scale="0.001 0.001 0.001"/>
      </geometry>
      <material name="Neobotix/Black"/>
      <!-- <color rgba="0 0 0 0"/>
	</material> -->
    </visual>
    <collision>
      <origin rpy="0 0 0" xyz="0 0 0"/>
      <geometry>
        <mesh filename="package://mp400_description/meshes/wsg50/WSG-FMF.stl" scale="0.001 0.001 0.001"/>
      </geometry>
    </collision>
    <contact_coefficients kd="1.0" kp="1000.0" mu="0"/>
  </link>
  <gazebo reference="wsg_50_finger_left">
    <material>Gazebo/Blue</material>
    <turnGravityOff>false</turnGravityOff>
  </gazebo>
  <!-- GRIPPER RIGHT -->
  <joint name="wsg_50_base_joint_gripper_right" type="prismatic">
    <limit effort="1.0" lower="0.0027" upper="0.055" velocity="1.0"/>
    <origin rpy="0 0 3.14159" xyz="0.0067 0 0"/>
    <parent link="wsg_50_base_link"/>
    <child link="wsg_50_gripper_right"/>
    <axis xyz="-1 0 0"/>
    <dynamics damping="100" friction="100"/>
    <limit effort="100" velocity="100"/>
  </joint>
  <transmission name="wsg_50_base_trans_right">
    <type>transmission_interface/SimpleTransmission</type>
    <joint name="wsg_50_base_joint_gripper_right">
      <hardwareInterface>hardware_interface/EffortJointInterface</hardwareInterface>
    </joint>
    <actuator name="wsg_50_base_motor_right">
      <hardwareInterface>hardware_interface/EffortJointInterface</hardwareInterface>
      <mechanicalReduction>1</mechanicalReduction>
      <motorTorqueConstant>1</motorTorqueConstant>
    </actuator>
  </transmission>
  <link name="wsg_50_gripper_right">
    <inertial>
      <mass value="0.1"/>
      <origin xyz="0 0 0"/>
      <inertia ixx="1.0" ixy="0.0" ixz="0.0" iyy="1.0" iyz="0.0" izz="1.0"/>
    </inertial>
    <visual>
      <origin rpy="0 0 0" xyz="0.0 0 0"/>
      <geometry>
        <mesh filename="package://mp400_description/meshes/wsg50/GUIDE_WSG50_110.stl" scale="0.001 0.001 0.001"/>
        <!--box size="0.0175 0.03 0.024"/-->
      </geometry>
      <material name="Neobotix/Black"/>
      <!--<color rgba="0 0 0 0"/>
	</material> -->
    </visual>
    <collision>
      <origin rpy="0 0 0" xyz="0 0 0"/>
      <geometry>
        <!--box size="0.0175 0.03 0.024"/-->
        <mesh filename="package://mp400_description/meshes/wsg50/GUIDE_WSG50_110.stl" scale="0.001 0.001 0.001"/>
      </geometry>
    </collision>
    <contact_coefficients kd="1.0" kp="1000.0" mu="0"/>
  </link>
  <gazebo reference="gripper_right">
    <material>Gazebo/White</material>
    <turnGravityOff>false</turnGravityOff>
  </gazebo>
  <!-- RIGHT FINGER -->
  <joint name="wsg_50_guide_joint_finger_right" type="fixed">
    <origin rpy="0 0 0" xyz="0 0 0.023"/>
    <parent link="wsg_50_gripper_right"/>
    <child link="wsg_50_finger_right"/>
    <dynamics damping="100" friction="100"/>
    <axis xyz="1 0 0"/>
    <limit effort="100" velocity="100"/>
  </joint>
  <link name="wsg_50_finger_right">
    <inertial>
      <mass value="0.1"/>
      <origin xyz="0 0 0"/>
      <inertia ixx="1.0" ixy="0.0" ixz="0.0" iyy="1.0" iyz="0.0" izz="1.0"/>
    </inertial>
    <visual>
      <origin rpy="0 0 0" xyz="0.0 0 0"/>
      <geometry>
        <mesh filename="package://mp400_description/meshes/wsg50/WSG-FMF.stl" scale="0.001 0.001 0.001"/>
      </geometry>
      <material name="Neobotix/Black"/>
      <!--<color rgba="0 0 0 0"/>
	</material> -->
    </visual>
    <collision>
      <origin rpy="0 0 0" xyz="0 0 0"/>
      <geometry>
        <mesh filename="package://mp400_description/meshes/wsg50/WSG-FMF.stl" scale="0.001 0.001 0.001"/>
      </geometry>
    </collision>
    <contact_coefficients kd="1.0" kp="1000.0" mu="0"/>
  </link>
  <gazebo reference="wsg_50_finger_right">
    <material>Gazebo/White</material>
    <turnGravityOff>false</turnGravityOff>
  </gazebo>
  <!-- joint between gripper_base_link and tcp_link -->
  <!--joint name="${name}_tcp_joint" type="fixed">
		<origin xyz="0 0 0.08" rpy="0 0 0" />
		<parent link="${name}_base_link"/>
		<child link="$arm_tcp_link"/>
	</joint>
	<link name="arm_tcp_link">
	</link-->
  <!-- joint between base_link and arm_0_link -->
  <joint name="arm_0_joint" type="fixed">
    <origin rpy="0 0 0" xyz="0 0 0"/>
    <parent link="schunk_base_link"/>
    <child link="arm_0_link"/>
  </joint>
  <link name="arm_0_link">
    <inertial>
      <origin rpy="0 0 0" xyz="0 0 0"/>
      <mass value="0.29364"/>
      <inertia ixx="0.01" ixy="0" ixz="0" iyy="0.01" iyz="0" izz="0.01"/>
    </inertial>
    <visual>
      <origin rpy="0 0 0" xyz="0 0 0"/>
      <geometry>
        <mesh filename="package://mp400_description/meshes/lwa4p/arm_0_link.dae"/>
      </geometry>
      <material name="Schunk/DarkGrey"/>
    </visual>
    <collision>
      <origin rpy="0 0 0" xyz="0 0 0"/>
      <geometry>
        <mesh filename="package://mp400_description/meshes/lwa4p/arm_0_link.stl"/>
      </geometry>
    </collision>
  </link>
  <joint name="arm_1_joint" type="revolute">
    <origin rpy="0 0 0" xyz="0 0 0.11"/>
    <parent link="arm_0_link"/>
    <child link="arm_1_link"/>
    <axis xyz="0 0 1"/>
    <calibration rising="2.1"/>
    <limit effort="0.1" lower="-2.95" upper="2.95" velocity="1.25"/>
  </joint>
  <link name="arm_1_link">
    <inertial>
      <mass value="0.29364"/>
      <inertia ixx="0.01" ixy="0" ixz="0" iyy="0.01" iyz="0" izz="0.01"/>
      <origin rpy="0 0 0" xyz="0 0 0"/>
    </inertial>
    <!--
      <inertial>
        <origin xyz="0 0 0" rpy="0 0 0" />
        <mass value="0.29364"/>
        <inertia ixx="0.01" ixy="0" ixz="0" iyy="0.01" iyz="0" izz="0.01" />
      </inertial>
-->
    <visual>
      <origin rpy="0 0 0" xyz="0 0 0"/>
      <geometry>
        <mesh filename="package://mp400_description/meshes/lwa4p/arm_1_link.dae"/>
      </geometry>
      <material name="Schunk/DarkGrey"/>
    </visual>
    <collision>
      <origin rpy="0 0 0" xyz="0 0 0"/>
      <geometry>
        <mesh filename="package://mp400_description/meshes/lwa4p/arm_1_link.stl"/>
      </geometry>
    </collision>
  </link>
  <!-- joint between arm_1_link and arm_2_link -->
  <joint name="arm_2_joint" type="revolute">
    <origin rpy="1.5708 0 0" xyz="0 0 0"/>
    <parent link="arm_1_link"/>
    <child link="arm_2_link"/>
    <axis xyz="0 0 1"/>
    <limit effort="0.1" lower="-2.95" upper="2.95" velocity="1.25"/>
    <!-- This is useful when the arm is mounted standing on a table -->
    <!-- <safety_controller k_position="20" k_velocity="25" soft_lower_limit="${-1.9 + safety_offset}" soft_upper_limit="${1.9 - safety_offset}" /> -->
  </joint>
  <link name="arm_2_link">
    <inertial>
      <mass value="0.29364"/>
      <inertia ixx="0.01" ixy="0" ixz="0" iyy="0.01" iyz="0" izz="0.01"/>
      <origin rpy="0 0 0" xyz="0 0 0"/>
    </inertial>
    <!--
      <inertial>
        <origin xyz="0 0 0" rpy="0 0 0"/>
        <mass value="1.68311"/>
        <inertia ixx="0.03" ixy="0" ixz="0" iyy="0.03" iyz="0" izz="0.03" />
      </inertial>
-->
    <visual>
      <origin rpy="0 0 0" xyz="0 0 0"/>
      <geometry>
        <mesh filename="package://mp400_description/meshes/lwa4p/arm_2_link.dae"/>
      </geometry>
      <material name="Schunk/Blue"/>
    </visual>
    <collision>
      <origin rpy="0 0 0" xyz="0 0 0"/>
      <geometry>
        <mesh filename="package://mp400_description/meshes/lwa4p/arm_2_link.stl"/>
      </geometry>
    </collision>
  </link>
  <!-- joint between arm_2_link and arm_3_link -->
  <joint name="arm_3_joint" type="revolute">
    <origin rpy="0 3.14159 0" xyz="0 0.350 0"/>
    <parent link="arm_2_link"/>
    <child link="arm_3_link"/>
    <axis xyz="0 0 1"/>
    <limit effort="0.1" lower="-2.95" upper="2.95" velocity="1.25"/>
    <safety_controller k_position="20" k_velocity="25" soft_lower_limit="-2.68" soft_upper_limit="2.68"/>
  </joint>
  <link name="arm_3_link">
    <inertial>
      <mass value="0.29364"/>
      <inertia ixx="0.01" ixy="0" ixz="0" iyy="0.01" iyz="0" izz="0.01"/>
      <origin rpy="0 0 0" xyz="0 0 0"/>
    </inertial>
    <!--
      <inertial>
        <origin xyz="0 0 0" rpy="0 0 0"/>
        <mass value="2.1"/>
        <inertia ixx="0.03" ixy="0" ixz="0" iyy="0.03" iyz="0" izz="0.03" />
      </inertial>
-->
    <visual>
      <origin rpy="0 0 0" xyz="0 0 0"/>
      <geometry>
        <mesh filename="package://mp400_description/meshes/lwa4p/arm_3_link.dae"/>
      </geometry>
      <material name="Schunk/DarkGrey"/>
    </visual>
    <collision>
      <origin rpy="0 0 0" xyz="0 0 0"/>
      <geometry>
        <mesh filename="package://mp400_description/meshes/lwa4p/arm_3_link.stl"/>
      </geometry>
    </collision>
  </link>
  <!-- joint between arm_3_link and arm_4_link -->
  <joint name="arm_4_joint" type="revolute">
    <origin rpy="-1.5708 3.14159 0" xyz="0 0 0"/>
    <parent link="arm_3_link"/>
    <child link="arm_4_link"/>
    <axis xyz="0 0 1"/>
    <limit effort="0.1" lower="-2.95" upper="2.95" velocity="1.25"/>
  </joint>
  <link name="arm_4_link">
    <inertial>
      <mass value="0.29364"/>
      <inertia ixx="0.01" ixy="0" ixz="0" iyy="0.01" iyz="0" izz="0.01"/>
      <origin rpy="0 0 0" xyz="0 0 0"/>
    </inertial>
    <!--
      <inertial>
        <origin xyz="0 0 0" rpy="0 0 0"/>
        <mass value="1.68311"/>
        <inertia ixx="0.03" ixy="0" ixz="0" iyy="0.03" iyz="0" izz="0.03" />
      </inertial>
-->
    <visual>
      <origin rpy="0 0 0" xyz="0 0 0"/>
      <geometry>
        <mesh filename="package://mp400_description/meshes/lwa4p/arm_4_link.dae"/>
      </geometry>
      <material name="Schunk/Blue"/>
    </visual>
    <collision>
      <origin rpy="0 0 0" xyz="0 0 0"/>
      <geometry>
        <mesh filename="package://mp400_description/meshes/lwa4p/arm_4_link.stl"/>
      </geometry>
    </collision>
  </link>
  <!-- joint between arm_4_link and arm_5_link -->
  <joint name="arm_5_joint" type="revolute">
    <origin rpy="1.5708 0 3.14159" xyz="0 0.005263 0.305"/>
    <parent link="arm_4_link"/>
    <child link="arm_5_link"/>
    <axis xyz="0 0 1"/>
    <limit effort="0.1" lower="-2.95" upper="2.95" velocity="1.25"/>
  </joint>
  <link name="arm_5_link">
    <inertial>
      <mass value="0.29364"/>
      <inertia ixx="0.01" ixy="0" ixz="0" iyy="0.01" iyz="0" izz="0.01"/>
      <origin rpy="0 0 0" xyz="0 0 0"/>
    </inertial>
    <!--
      <inertial>
        <origin xyz="0 0 0" rpy="0 0 0"/>
        <mass value="0.807"/>
        <inertia ixx="0.03" ixy="0" ixz="0" iyy="0.03" iyz="0" izz="0.03" />
      </inertial>
-->
    <visual>
      <origin rpy="0 0 0" xyz="0 0 0"/>
      <geometry>
        <mesh filename="package://mp400_description/meshes/lwa4p/arm_5_link.dae"/>
      </geometry>
      <material name="Schunk/DarkGrey"/>
    </visual>
    <collision>
      <origin rpy="0 0 0" xyz="0 0 0"/>
      <geometry>
        <mesh filename="package://mp400_description/meshes/lwa4p/arm_5_link.stl"/>
      </geometry>
    </collision>
  </link>
  <!-- joint between arm_5_link and arm_6_link -->
  <joint name="arm_6_joint" type="revolute">
    <origin rpy="-1.5708 0 0" xyz="0 0 0"/>
    <parent link="arm_5_link"/>
    <child link="arm_6_link"/>
    <axis xyz="0 0 1"/>
    <limit effort="20.1" lower="-2.947" upper="2.947" velocity="1.25"/>
    <!--safety_controller k_position="20" k_velocity="25" soft_lower_limit="${-2.09 + 0.01}" soft_upper_limit="${2.09 - 0.01}" /-->
  </joint>
  <link name="arm_6_link">
    <inertial>
      <mass value="0.29364"/>
      <inertia ixx="0.01" ixy="0" ixz="0" iyy="0.01" iyz="0" izz="0.01"/>
      <origin rpy="0 0 0" xyz="0 0 0"/>
    </inertial>
    <!--
      <inertial>
        <origin xyz="0 0 0" rpy="0 0 0"/>
        <mass value="0.819"/>
        <inertia ixx="0.01" ixy="0" ixz="0" iyy="0.01" iyz="0" izz="0.01" />
      </inertial>
-->
    <visual>
      <origin rpy="0 0 0" xyz="0 0 0"/>
      <geometry>
        <mesh filename="package://mp400_description/meshes/lwa4p/arm_6_link.dae"/>
      </geometry>
      <material name="Schunk/DarkGrey"/>
    </visual>
    <collision>
      <origin rpy="0 0 0" xyz="0 0 0"/>
      <geometry>
        <mesh filename="package://mp400_description/meshes/lwa4p/arm_6_link.stl"/>
      </geometry>
    </collision>
  </link>
  <!-- joint between arm_6_link and tcp_link -->
  <joint name="arm_tcp_joint" type="fixed">
    <origin rpy="0 0 0" xyz="0 0 0.08"/>
    <parent link="arm_6_link"/>
    <child link="arm_tcp_link"/>
  </joint>
  <link name="arm_tcp_link">
    </link>
  <gazebo reference="arm_0_link">
    <gravity>true</gravity>
    <self_collide>false</self_collide>
    <material value="Schunk/DarkGrey"/>
  </gazebo>
  <gazebo reference="arm_1_link">
    <gravity>true</gravity>
    <self_collide>false</self_collide>
    <material value="Schunk/DarkGrey"/>
  </gazebo>
  <gazebo reference="arm_2_link">
    <gravity>true</gravity>
    <self_collide>false</self_collide>
    <material value="Schunk/Blue"/>
  </gazebo>
  <gazebo reference="arm_3_link">
    <gravity>true</gravity>
    <self_collide>false</self_collide>
    <material value="Schunk/DarkGrey"/>
  </gazebo>
  <gazebo reference="arm_4_link">
    <gravity>true</gravity>
    <self_collide>false</self_collide>
    <material value="Schunk/Blue"/>
  </gazebo>
  <gazebo reference="arm_5_link">
    <gravity>true</gravity>
    <self_collide>false</self_collide>
    <material value="Schunk/DarkGrey"/>
  </gazebo>
  <gazebo reference="arm_6_link">
    <gravity>true</gravity>
    <self_collide>false</self_collide>
    <material value="Schunk/DarkGrey"/>
  </gazebo>
  <transmission name="arm_1_trans">
    <type>transmission_interface/SimpleTransmission</type>
    <joint name="arm_1_joint">
      <hardwareInterface>hardware_interface/EffortJointInterface</hardwareInterface>
      <!--<hardwareInterface>PositionJointInterface</hardwareInterface>
        <hardwareInterface>VelocityJointInterface</hardwareInterface>-->
    </joint>
    <actuator name="arm_1_motor">
      <hardwareInterface>hardware_interface/EffortJointInterface</hardwareInterface>
      <mechanicalReduction>1</mechanicalReduction>
    </actuator>
  </transmission>
  <transmission name="arm_2_trans">
    <type>transmission_interface/SimpleTransmission</type>
    <joint name="arm_2_joint">
      <hardwareInterface>hardware_interface/EffortJointInterface</hardwareInterface>
      <!--<hardwareInterface>PositionJointInterface</hardwareInterface>
        <hardwareInterface>VelocityJointInterface</hardwareInterface>-->
    </joint>
    <actuator name="arm_2_motor">
      <hardwareInterface>hardware_interface/EffortJointInterface</hardwareInterface>
      <mechanicalReduction>1</mechanicalReduction>
    </actuator>
  </transmission>
  <transmission name="arm_3_trans">
    <type>transmission_interface/SimpleTransmission</type>
    <joint name="arm_3_joint">
      <hardwareInterface>hardware_interface/EffortJointInterface</hardwareInterface>
      <!--<hardwareInterface>PositionJointInterface</hardwareInterface>
        <hardwareInterface>VelocityJointInterface</hardwareInterface>-->
    </joint>
    <actuator name="arm_3_motor">
      <hardwareInterface>hardware_interface/EffortJointInterface</hardwareInterface>
      <mechanicalReduction>1</mechanicalReduction>
    </actuator>
  </transmission>
  <transmission name="arm_4_trans">
    <type>transmission_interface/SimpleTransmission</type>
    <joint name="arm_4_joint">
      <hardwareInterface>hardware_interface/EffortJointInterface</hardwareInterface>
      <!--<hardwareInterface>PositionJointInterface</hardwareInterface>
        <hardwareInterface>VelocityJointInterface</hardwareInterface>-->
    </joint>
    <actuator name="arm_4_motor">
      <hardwareInterface>hardware_interface/EffortJointInterface</hardwareInterface>
      <mechanicalReduction>1</mechanicalReduction>
    </actuator>
  </transmission>
  <transmission name="arm_5_trans">
    <type>transmission_interface/SimpleTransmission</type>
    <joint name="arm_5_joint">
      <hardwareInterface>hardware_interface/EffortJointInterface</hardwareInterface>
      <!--<hardwareInterface>PositionJointInterface</hardwareInterface>
        <hardwareInterface>VelocityJointInterface</hardwareInterface>-->
    </joint>
    <actuator name="arm_5_motor">
      <hardwareInterface>hardware_interface/EffortJointInterface</hardwareInterface>
      <mechanicalReduction>1</mechanicalReduction>
    </actuator>
  </transmission>
  <transmission name="arm_6_trans">
    <type>transmission_interface/SimpleTransmission</type>
    <joint name="arm_6_joint">
      <hardwareInterface>hardware_interface/EffortJointInterface</hardwareInterface>
      <!--<hardwareInterface>PositionJointInterface</hardwareInterface>
        <hardwareInterface>VelocityJointInterface</hardwareInterface>-->
    </joint>
    <actuator name="arm_6_motor">
      <hardwareInterface>hardware_interface/EffortJointInterface</hardwareInterface>
      <mechanicalReduction>1</mechanicalReduction>
    </actuator>
  </transmission>
  <material name="aluminum">
    <color rgba="0.5 0.5 0.5 1"/>
  </material>
  <!-- camera body, with origin at bottom screw mount -->
  <joint name="camera_joint" type="fixed">
    <origin rpy="0 0 -3.14159265359" xyz="0 0 0"/>
    <parent link="base_link"/>
    <child link="camera_link"/>
  </joint>
  <link name="camera_link">
    <visual>
      <origin rpy="1.57079632679 0 1.57079632679" xyz="-0.1351 0.0 1.3125"/>
      <!--<origin xyz="-0.25 0.0 1.425" rpy="${M_PI/2} 0 ${-M_PI/2}"/>-->
      <geometry>
        <!-- <box size="${d435_cam_width} ${d435_cam_height} ${d435_cam_depth}"/> -->
        <mesh filename="package://realsense2_camera/meshes/d435.dae"/>
        <!--<mesh filename="package://realsense2_camera/meshes/d435/d435.dae" />-->
      </geometry>
      <material name="aluminum"/>
    </visual>
    <collision>
      <origin rpy="0 0 0" xyz="0.0 0.0 0.0125"/>
      <!--<origin xyz="0.0 0.0 1.425" rpy="0 0 0"/>-->
      <geometry>
        <box size="0.02505 0.09 0.025"/>
      </geometry>
    </collision>
    <inertial>
      <!-- The following are not reliable values, and should not be used for modeling -->
      <mass value="0.564"/>
      <origin xyz="0 0 0"/>
      <inertia ixx="0.003881243" ixy="0.0" ixz="0.0" iyy="0.000498940" iyz="0.0" izz="0.003879257"/>
    </inertial>
  </link>
  <!-- camera depth joints and links -->
  <joint name="camera_depth_joint" type="fixed">
    <origin rpy="0 0 0" xyz="0.0149 0.0175 0.0125"/>
    <parent link="camera_link"/>
    <child link="camera_depth_frame"/>
  </joint>
  <link name="camera_depth_frame"/>
  <joint name="camera_depth_optical_joint" type="fixed">
    <origin rpy="-1.57079632679 0 -1.57079632679" xyz="0 0 0"/>
    <parent link="camera_depth_frame"/>
    <child link="camera_depth_optical_frame"/>
  </joint>
  <link name="camera_depth_optical_frame"/>
  <!-- camera left IR joints and links -->
  <joint name="camera_left_ir_joint" type="fixed">
    <origin rpy="0 0 0" xyz="0 0.0 0"/>
    <parent link="camera_depth_frame"/>
    <child link="camera_left_ir_frame"/>
  </joint>
  <link name="camera_left_ir_frame"/>
  <joint name="camera_left_ir_optical_joint" type="fixed">
    <origin rpy="-1.57079632679 0 -1.57079632679" xyz="0 0 0"/>
    <parent link="camera_left_ir_frame"/>
    <child link="camera_left_ir_optical_frame"/>
  </joint>
  <link name="camera_left_ir_optical_frame"/>
  <!-- camera right IR joints and links -->
  <joint name="camera_right_ir_joint" type="fixed">
    <origin rpy="0 0 0" xyz="0 -0.05 0"/>
    <parent link="camera_depth_frame"/>
    <child link="camera_right_ir_frame"/>
  </joint>
  <link name="camera_right_ir_frame"/>
  <joint name="camera_right_ir_optical_joint" type="fixed">
    <origin rpy="-1.57079632679 0 -1.57079632679" xyz="0 0 0"/>
    <parent link="camera_right_ir_frame"/>
    <child link="camera_right_ir_optical_frame"/>
  </joint>
  <link name="camera_right_ir_optical_frame"/>
  <!-- camera color joints and links -->
  <joint name="camera_color_joint" type="fixed">
    <origin rpy="0 0 0" xyz="0 0.015 0"/>
    <parent link="camera_depth_frame"/>
    <child link="camera_color_frame"/>
  </joint>
  <link name="camera_color_frame"/>
  <joint name="camera_color_optical_joint" type="fixed">
    <origin rpy="-1.57079632679 0 -1.57079632679" xyz="0 0 0"/>
    <parent link="camera_color_frame"/>
    <child link="camera_color_optical_frame"/>
  </joint>
  <link name="camera_color_optical_frame"/>
  <!--++++++++++++++++++++++++++++++base_link++++++++++++++++++++++++++++++++++++++++++++++++++++-->
  <!--++++++++++++++++++++body++++++++++++++++++++++++++++-->
  <link name="base_link">
    <!--inertial>
        <mass value="67.010" />
        <origin xyz="0.0 0.0 0.234" rpy="0 0 0"/>
        <inertia ixx="1417853.715" ixy="17813.155" ixz="-21078.206"
                 iyy="2030191.708" iyz="-4813.295"
                 izz="2180211.662" />
      </inertial-->
    <inertial>
      <mass value="5.67"/>
      <origin rpy="0 0 0" xyz="0 0 0.0"/>
      <inertia ixx="0.07" ixy="0.0" ixz="0.0" iyy="0.08" iyz="0.0" izz="0.1"/>
    </inertial>
    <visual name="body">
      <!--origin xyz="0.0 0.0 0.234" rpy="0 0 1.57" /-->
      <!-- for cylinder -->
      <origin rpy="0 0 1.57" xyz="0.0 0.0 0.0"/>
      <!-- for STL -->
      <geometry>
        <mesh filename="package://mp400_description/meshes/mp400/mp_400_body.stl" scale="0.001 0.001 0.001"/>
        <!--cylinder length="0.381" radius="0.2545"/-->
        <!--box size="0.445 0.277 0.17"/-->
      </geometry>
      <material name="Neobotix/Yellow"/>
    </visual>
    <collision name="body_collision">
      <origin rpy="0 0 0" xyz="0.0 0.0 0.234"/>
      <geometry>
        <!--box size="0.445 0.277 0.17"/-->
        <cylinder length="0.381" radius="0.2545"/>
      </geometry>
    </collision>
    <!--+++++++++++++++++++castor_front++++++++++++++++++++++++-->
    <visual name="castor_front_visual">
      <origin rpy="0 0 0" xyz="0.2 0 0.018"/>
      <geometry>
        <sphere radius="0.016"/>
      </geometry>
      <material name="Neobotix/Black"/>
    </visual>
    <collision name="castor_front_collision">
      <origin rpy="0 0 0" xyz="0.2 0 0.018 "/>
      <geometry>
        <sphere radius="0.016"/>
      </geometry>
    </collision>
    <!--+++++++++++++++++++castor_back++++++++++++++++++++++++-->
    <visual name="castor_back_visual">
      <origin rpy="0 0 0" xyz="-0.2 0 0.018"/>
      <geometry>
        <sphere radius="0.016"/>
      </geometry>
      <material name="Neobotix/Black"/>
    </visual>
    <collision name="castor_back_collision">
      <origin rpy="0 0 0" xyz="-0.2 0 0.018 "/>
      <!--pose>0.3 0 -0.12 0 -0 0</pose-->
      <geometry>
        <sphere radius="0.016"/>
      </geometry>
    </collision>
  </link>
  <!--+++++++++++++++++++wheel_left_link++++++++++++++++++++++++-->
  <link name="wheel_left_link" type="wheel">
    <inertial>
      <mass value="1.5"/>
      <origin rpy="0 0 0" xyz="0.0 0.0 -0.016"/>
      <inertia ixx="0.0051" ixy="0" ixz="0" iyy="0.0051" iyz="0" izz="0.009"/>
    </inertial>
    <visual>
      <origin rpy="0 0 0" xyz="0.0 0.0 -0.016"/>
      <geometry>
        <!--mesh filename="package://mp400_description/meshes/mp400/MP-400-WHEEL.STL" scale="0.001 0.001 0.001"/-->
        <cylinder length="0.03" radius="0.075"/>
      </geometry>
      <material name="Neobotix/Black"/>
    </visual>
    <collision>
      <origin rpy="0 0 0" xyz="0.0 0.0 -0.016"/>
      <geometry>
        <cylinder length="0.03" radius="0.075"/>
      </geometry>
    </collision>
  </link>
  <!--+++++++++++++++++++wheel_left_joint++++++++++++++++++++++++-->
  <joint name="wheel_left_joint" type="revolute">
    <origin rpy="0 1.57 1.57" xyz="0 -0.2645 0.075"/>
    <axis xyz="0 0 1"/>
    <limit effort="1000.0" lower="-1e+16" upper="1e+16" velocity="3.5"/>
    <joint_properties damping="0.0" friction="0.0"/>
    <parent link="base_link"/>
    <child link="wheel_left_link"/>
  </joint>
  <!--+++++++++++++++++++wheel_right_link++++++++++++++++++++++++-->
  <link name="wheel_right_link" type="wheel">
    <inertial>
      <mass value="1.5"/>
      <origin rpy="0 0 0" xyz="0 0.0 0.016"/>
      <inertia ixx="0.0051" ixy="0" ixz="0" iyy="0.0051" iyz="0" izz="0.009"/>
    </inertial>
    <visual>
      <origin rpy="0 0 0" xyz="0 0.0 0.016"/>
      <geometry>
        <!--mesh filename="package://mp400_description/meshes/mp400/MP-400-WHEEL.STL" scale="0.001 0.001 0.001"/-->
        <cylinder length="0.03" radius="0.075"/>
      </geometry>
      <material name="Neobotix/Black"/>
    </visual>
    <collision>
      <origin rpy="0 0 0" xyz="0.0 0.0 0.016"/>
      <geometry>
        <cylinder length="0.03" radius="0.075"/>
      </geometry>
    </collision>
  </link>
  <!--+++++++++++++++++++wheel_right_joint++++++++++++++++++++++++-->
  <joint name="wheel_right_joint" type="revolute">
    <origin rpy="0 1.57 1.57" xyz="0 0.2645 0.075"/>
    <axis xyz="0 0 1"/>
    <limit effort="1000.0" lower="-1e+16" upper="1e+16" velocity="3.5"/>
    <joint_properties damping="0.0" friction="0.0"/>
    <parent link="base_link"/>
    <child link="wheel_right_link"/>
  </joint>
  <!--+++++++++++++++++++laserscanner_front_joint++++++++++++++++++++++++-->
  <joint name="laserscanner_front_joint" type="fixed">
    <axis xyz="0 1 0"/>
    <origin rpy="3.14 0 0" xyz="0.230 0 0.110"/>
    <parent link="base_link"/>
    <child link="laserscanner_front_link"/>
  </joint>
  <!--+++++++++++++++++++laserscanner_front_link++++++++++++++++++++++++-->
  <link name="laserscanner_front_link" type="laser">
    <inertial>
      <mass value="0.001"/>
      <origin rpy="0 0 0" xyz="0 0 0"/>
      <inertia ixx="0.0001" ixy="0" ixz="0" iyy="0.000001" iyz="0" izz="0.0001"/>
    </inertial>
    <visual>
      <origin rpy="0 0 -1.57" xyz="0 0 0"/>
      <geometry>
        <mesh filename="package://mp400_description/meshes/mp400/sick_s300.stl"/>
      </geometry>
      <material name="Neobotix/Yellow"/>
    </visual>
    <collision>
      <origin rpy="0 0 0" xyz="0 0 0"/>
      <geometry>
        <cylinder length="0.154" radius="0.053"/>
      </geometry>
    </collision>
  </link>
  <!--+++++++++++++++++++laserscanner_back_joint++++++++++++++++++++++++-->
  <joint name="laserscanner_back_joint" type="fixed">
    <axis xyz="0 1 0"/>
    <origin rpy="3.14 0 3.14" xyz="-0.354 0 0.110"/>
    <parent link="base_link"/>
    <child link="laserscanner_back_link"/>
  </joint>
  <!--+++++++++++++++++++laserscanner_back_link++++++++++++++++++++++++-->
  <link name="laserscanner_back_link" type="laser">
    <inertial>
      <mass value="0.001"/>
      <origin rpy="0 0 0" xyz="0 0 0"/>
      <inertia ixx="0.0001" ixy="0" ixz="0" iyy="0.000001" iyz="0" izz="0.0001"/>
    </inertial>
    <visual>
      <origin rpy="0 0 -1.57" xyz="0 0 0"/>
      <geometry>
        <mesh filename="package://mp400_description/meshes/mp400/sick_s300.stl"/>
      </geometry>
      <material name="Neobotix/Yellow"/>
    </visual>
    <collision>
      <origin rpy="0 0 0" xyz="0 0 0"/>
      <geometry>
        <cylinder length="0.154" radius="0.053"/>
      </geometry>
    </collision>
  </link>
  <!--+++++++++++++++++arm_mount_joint+++++++++++++++++++-->
  <joint name="baselink_to_arm_mount" type="fixed">
    <parent link="base_link"/>
    <child link="arm_mount"/>
    <origin rpy="0 0 0" xyz="0.0 0.0 0.222"/>
  </joint>
  <!--+++++++++++++++++arm_mount_link+++++++++++++++++++-->
  <link name="arm_mount">
    <visual>
      <geometry>
        <box size="0.45 0.45 0.01"/>
      </geometry>
      <origin rpy="0 0 0" xyz="0.025 0 0.223"/>
      <material name="Schunk/LightGrey"/>
    </visual>
  </link>
  <joint name="arm_robot_joint" type="fixed">
    <parent link="arm_mount"/>
    <child link="schunk_base_link"/>
    <origin rpy="0 0 0" xyz="0.025 0 0.223"/>
  </joint>
</robot>
